Workbook

Sheet 2022
A1: Round | B1: Match | C1: Team1 | D1: Team2 | E1: Winner | F1: NetRankWinner | G1: NRW | H1: NetRankAdjWinner | I1: NRAW | J1: AvgOppNetWinner | K1: AONW | L1: AvgOppNetAdjWinner | M1: AONAW | N1: NetSosWinner | O1: NSW | P1: NetSosAdjWinner | Q1: NSAW | R1: WabWinner | S1: WW | T1: WabAdjWinner | U1: WAW
A2: Round of 64 | B2: 1 | C2: Gonzaga | D2: Georgia State | E2: Gonzaga | F2: Gonzaga | G2: =if(E2=F2, "1", "0") -> 1 | H2: Gonzaga | I2: =if(E2=H2, "1", "0") -> 1 | J2: Gonzaga | K2: =if(E2=J2, "1", "0") -> 1 | L2: Gonzaga | M2: =if(E2=L2, "1", "0") -> 1 | N2: Gonzaga | O2: =if(E2=N2, "1", "0") -> 1 | P2: Gonzaga | Q2: =if(E2=P2, "1", "0") -> 1 | R2: Gonzaga | S2: =if(R2=E2, "1", "0") -> 1 | T2: Gonzaga | U2: =If(T2=E2,"1","0") -> 1
A3: Round of 64 | B3: 2 | C3: Boise State | D3: Memphis | E3: Memphis | F3: Boise State | G3: =if(E3=F3, "1", "0") -> 0 | H3: Memphis | I3: =if(E3=H3, "1", "0") -> 1 | J3: Memphis | K3: =if(E3=J3, "1", "0") -> 1 | L3: Memphis | M3: =if(E3=L3, "1", "0") -> 1 | N3: Memphis | O3: =if(E3=N3, "1", "0") -> 1 | P3: Memphis | Q3: =if(E3=P3, "1", "0") -> 1 | R3: Boise State | S3: =if(R3=E3, "1", "0") -> 0 | T3: Boise State | U3: =If(T3=E3,"1","0") -> 0
A4: Round of 64 | B4: 3 | C4: UConn | D4: New Mexico State | E4: New Mexico State | F4: UConn | G4: =if(E4=F4, "1", "0") -> 0 | H4: UConn | I4: =if(E4=H4, "1", "0") -> 0 | J4: UConn | K4: =if(E4=J4, "1", "0") -> 0 | L4: UConn | M4: =if(E4=L4, "1", "0") -> 0 | N4: UConn | O4: =if(E4=N4, "1", "0") -> 0 | P4: UConn | Q4: =if(E4=P4, "1", "0") -> 0 | R4: UConn | S4: =if(R4=E4, "1", "0") -> 0 | T4: UConn | U4: =If(T4=E4,"1","0") -> 0
A5: Round of 64 | B5: 4 | C5: Arkansas | D5: Vermont | E5: Arkansas | F5: Arkansas | G5: =if(E5=F5, "1", "0") -> 1 | H5: Arkansas | I5: =if(E5=H5, "1", "0") -> 1 | J5: Arkansas | K5: =if(E5=J5, "1", "0") -> 1 | L5: Arkansas | M5: =if(E5=L5, "1", "0") -> 1 | N5: Arkansas | O5: =if(E5=N5, "1", "0") -> 1 | P5: Arkansas | Q5: =if(E5=P5, "1", "0") -> 1 | R5: Arkansas | S5: =if(R5=E5, "1", "0") -> 1 | T5: Arkansas | U5: =If(T5=E5,"1","0") -> 1
A6: Round of 64 | B6: 5 | C6: Alabama | D6: Notre Dame | E6: Notre Dame | F6: Alabama | G6: =if(E6=F6, "1", "0") -> 0 | H6: Alabama | I6: =if(E6=H6, "1", "0") -> 0 | J6: Alabama | K6: =if(E6=J6, "1", "0") -> 0 | L6: Alabama | M6: =if(E6=L6, "1", "0") -> 0 | N6: Alabama | O6: =if(E6=N6, "1", "0") -> 0 | P6: Alabama | Q6: =if(E6=P6, "1", "0") -> 0 | R6: Alabama | S6: =if(R6=E6, "1", "0") -> 0 | T6: Alabama | U6: =If(T6=E6,"1","0") -> 0
A7: Round of 64 | B7: 6 | C7: Texas Tech | D7: Montana State | E7: Texas Tech | F7: Texas Tech | G7: =if(E7=F7, "1", "0") -> 1 | H7: Texas Tech | I7: =if(E7=H7, "1", "0") -> 1 | J7: Texas Tech | K7: =if(E7=J7, "1", "0") -> 1 | L7: Texas Tech | M7: =if(E7=L7, "1", "0") -> 1 | N7: Texas Tech | O7: =if(E7=N7, "1", "0") -> 1 | P7: Texas Tech | Q7: =if(E7=P7, "1", "0") -> 1 | R7: Texas Tech | S7: =if(R7=E7, "1", "0") -> 1 | T7: Texas Tech | U7: =If(T7=E7,"1","0") -> 1
A8: Round of 64 | B8: 7 | C8: Michigan State | D8: Davidson | E8: Michigan State | F8: Michigan State | G8: =if(E8=F8, "1", "0") -> 1 | H8: Davidson | I8: =if(E8=H8, "1", "0") -> 0 | J8: Michigan State | K8: =if(E8=J8, "1", "0") -> 1 | L8: Michigan State | M8: =if(E8=L8, "1", "0") -> 1 | N8: Michigan State | O8: =if(E8=N8, "1", "0") -> 1 | P8: Michigan State | Q8: =if(E8=P8, "1", "0") -> 1 | R8: Michigan State | S8: =if(R8=E8, "1", "0") -> 1 | T8: Davidson | U8: =If(T8=E8,"1","0") -> 0
A9: Round of 64 | B9: 8 | C9: Duke | D9: Cal State Fullerton | E9: Duke | F9: Duke | G9: =if(E9=F9, "1", "0") -> 1 | H9: Duke | I9: =if(E9=H9, "1", "0") -> 1 | J9: Duke | K9: =if(E9=J9, "1", "0") -> 1 | L9: Duke | M9: =if(E9=L9, "1", "0") -> 1 | N9: Duke | O9: =if(E9=N9, "1", "0") -> 1 | P9: Duke | Q9: =if(E9=P9, "1", "0") -> 1 | R9: Duke | S9: =if(R9=E9, "1", "0") -> 1 | T9: Duke | U9: =If(T9=E9,"1","0") -> 1
A10: Round of 64 | B10: 9 | C10: Baylor | D10: Norfolk State | E10: Baylor | F10: Baylor | G10: =if(E10=F10, "1", "0") -> 1 | H10: Baylor | I10: =if(E10=H10, "1", "0") -> 1 | J10: Baylor | K10: =if(E10=J10, "1", "0") -> 1 | L10: Baylor | M10: =if(E10=L10, "1", "0") -> 1 | N10: Baylor | O10: =if(E10=N10, "1", "0") -> 1 | P10: Baylor | Q10: =if(E10=P10, "1", "0") -> 1 | R10: Baylor | S10: =if(R10=E10, "1", "0") -> 1 | T10: Baylor | U10: =If(T10=E10,"1","0") -> 1
A11: Round of 64 | B11: 10 | C11: North Carolina | D11: Marquette | E11: North Carolina | F11: 0rth Carolina | G11: =if(E11=F11, "1", "0") -> 0 | H11: 0rth Carolina | I11: =if(E11=H11, "1", "0") -> 0 | J11: Marquette | K11: =if(E11=J11, "1", "0") -> 0 | L11: Marquette | M11: =if(E11=L11, "1", "0") -> 0 | N11: Marquette | O11: =if(E11=N11, "1", "0") -> 0 | P11: Marquette | Q11: =if(E11=P11, "1", "0") -> 0 | R11: 0rth Carolina | S11: =if(R11=E11, "1", "0") -> 0 | T11: 0rth Carolina | U11: =If(T11=E11,"1","0") -> 0
A12: Round of 64 | B12: 11 | C12: Saint Mary's | D12: Indiana | E12: Saint Mary's | F12: Saint Mary's | G12: =if(E12=F12, "1", "0") -> 1 | H12: Saint Mary's | I12: =if(E12=H12, "1", "0") -> 1 | J12: Indiana | K12: =if(E12=J12, "1", "0") -> 0 | L12: Indiana | M12: =if(E12=L12, "1", "0") -> 0 | N12: Indiana | O12: =if(E12=N12, "1", "0") -> 0 | P12: Indiana | Q12: =if(E12=P12, "1", "0") -> 0 | R12: Saint Mary's | S12: =if(R12=E12, "1", "0") -> 1 | T12: Saint Mary's | U12: =If(T12=E12,"1","0") -> 1
A13: Round of 64 | B13: 12 | C13: UCLA | D13: Akron | E13: UCLA | F13: UCLA | G13: =if(E13=F13, "1", "0") -> 1 | H13: UCLA | I13: =if(E13=H13, "1", "0") -> 1 | J13: UCLA | K13: =if(E13=J13, "1", "0") -> 1 | L13: UCLA | M13: =if(E13=L13, "1", "0") -> 1 | N13: UCLA | O13: =if(E13=N13, "1", "0") -> 1 | P13: UCLA | Q13: =if(E13=P13, "1", "0") -> 1 | R13: UCLA | S13: =if(R13=E13, "1", "0") -> 1 | T13: UCLA | U13: =If(T13=E13,"1","0") -> 1
... A64: Championship | B64: 1 | C64: North Carolina | D64: Kansas | E64: Kansas | F64: Gonzaga | G64: =if(E64=F64, "1", "0") -> 0 | H64: Kansas | I64: =if(E64=H64, "1", "0") -> 1 | J64: Alabama | K64: =if(E64=J64, "1", "0") -> 0 | L64: Illi0is | M64: =if(E64=L64, "1", "0") -> 0 | N64: Alabama | O64: =if(E64=N64, "1", "0") -> 0 | P64: Iowa State | Q64: =if(E64=P64, "1", "0") -> 0 | R64: Kansas | S64: =if(R64=E64, "1", "0") -> 1 | T64: Villa0va | U64: =If(T64=E64,"1","0") -> 0

Sheet 2023
A1: Round | B1: Match | C1: Team1 | D1: Team2 | E1: Winner | F1: NetRankWinner | G1: NRW | H1: NetRankAdjWinner | I1: NRAW | J1: AvgOppNetWinner | K1: AONW | L1: AvgOppNetAdjWinner | M1: AONAW | N1: NetSosWinner | O1: NSW | P1: NetSosAdjWinner | Q1: NSAW | R1: WabWinner | S1: WW | T1: WabAdjWinner | U1: WAW
A2: Round of 64 | B2: 1 | C2: Alabama | D2: Texas A&M-CC | E2: Alabama | F2: Alabama | G2: =if(E2=F2, "1", "0") -> 1 | H2: Alabama | I2: =if(E2=H2, "1", "0") -> 1 | J2: Alabama | K2: =if(E2=J2, "1", "0") -> 1 | L2: Alabama | M2: =if(E2=L2, "1", "0") -> 1 | N2: Alabama | O2: =if(E2=N2, "1", "0") -> 1 | P2: Alabama | Q2: =if(E2=P2, "1", "0") -> 1 | R2: Alabama | S2: =IF(R2=E2,"1","0") -> 1 | T2: Alabama | U2: =IF(T2=E2,"1","0") -> 1
A3: Round of 64 | B3: 2 | C3: Maryland | D3: West Virginia | E3: Maryland | F3: West Virginia | G3: =if(E3=F3, "1", "0") -> 0 | H3: West Virginia | I3: =if(E3=H3, "1", "0") -> 0 | J3: West Virginia | K3: =if(E3=J3, "1", "0") -> 0 | L3: West Virginia | M3: =if(E3=L3, "1", "0") -> 0 | N3: West Virginia | O3: =if(E3=N3, "1", "0") -> 0 | P3: West Virginia | Q3: =if(E3=P3, "1", "0") -> 0 | R3: West Virginia | S3: =IF(R3=E3,"1","0") -> 0 | T3: Maryland | U3: =IF(T3=E3,"1","0") -> 1
A4: Round of 64 | B4: 3 | C4: San Diego State | D4: Charleston | E4: San Diego State | F4: San Diego State | G4: =if(E4=F4, "1", "0") -> 1 | H4: San Diego State | I4: =if(E4=H4, "1", "0") -> 1 | J4: San Diego State | K4: =if(E4=J4, "1", "0") -> 1 | L4: San Diego State | M4: =if(E4=L4, "1", "0") -> 1 | N4: San Diego State | O4: =if(E4=N4, "1", "0") -> 1 | P4: San Diego State | Q4: =if(E4=P4, "1", "0") -> 1 | R4: San Diego State | S4: =IF(R4=E4,"1","0") -> 1 | T4: San Diego State | U4: =IF(T4=E4,"1","0") -> 1
A5: Round of 64 | B5: 4 | C5: Virginia | D5: Furman | E5: Furman | F5: Virginia | G5: =if(E5=F5, "1", "0") -> 0 | H5: Virginia | I5: =if(E5=H5, "1", "0") -> 0 | J5: Virginia | K5: =if(E5=J5, "1", "0") -> 0 | L5: Virginia | M5: =if(E5=L5, "1", "0") -> 0 | N5: Virginia | O5: =if(E5=N5, "1", "0") -> 0 | P5: Virginia | Q5: =if(E5=P5, "1", "0") -> 0 | R5: Virginia | S5: =IF(R5=E5,"1","0") -> 0 | T5: Virginia | U5: =IF(T5=E5,"1","0") -> 0
A6: Round of 64 | B6: 5 | C6: Creighton | D6: NC State | E6: Creighton | F6: Creighton | G6: =if(E6=F6, "1", "0") -> 1 | H6: Creighton | I6: =if(E6=H6, "1", "0") -> 1 | J6: Creighton | K6: =if(E6=J6, "1", "0") -> 1 | L6: Creighton | M6: =if(E6=L6, "1", "0") -> 1 | N6: Creighton | O6: =if(E6=N6, "1", "0") -> 1 | P6: Creighton | Q6: =if(E6=P6, "1", "0") -> 1 | R6: Creighton | S6: =IF(R6=E6,"1","0") -> 1 | T6: Creighton | U6: =IF(T6=E6,"1","0") -> 1
A7: Round of 64 | B7: 6 | C7: Baylor | D7: UCSB | E7: Baylor | F7: Baylor | G7: =if(E7=F7, "1", "0") -> 1 | H7: Baylor | I7: =if(E7=H7, "1", "0") -> 1 | J7: Baylor | K7: =if(E7=J7, "1", "0") -> 1 | L7: Baylor | M7: =if(E7=L7, "1", "0") -> 1 | N7: Baylor | O7: =if(E7=N7, "1", "0") -> 1 | P7: Baylor | Q7: =if(E7=P7, "1", "0") -> 1 | R7: Baylor | S7: =IF(R7=E7,"1","0") -> 1 | T7: Baylor | U7: =IF(T7=E7,"1","0") -> 1
A8: Round of 64 | B8: 7 | C8: Missouri | D8: Utah State | E8: Missouri | F8: Utah State | G8: =if(E8=F8, "1", "0") -> 0 | H8: Utah State | I8: =if(E8=H8, "1", "0") -> 0 | J8: Utah State | K8: =if(E8=J8, "1", "0") -> 0 | L8: Utah State | M8: =if(E8=L8, "1", "0") -> 0 | N8: Missouri | O8: =if(E8=N8, "1", "0") -> 1 | P8: Missouri | Q8: =if(E8=P8, "1", "0") -> 1 | R8: Utah State | S8: =IF(R8=E8,"1","0") -> 0 | T8: Missouri | U8: =IF(T8=E8,"1","0") -> 1
A9: Round of 64 | B9: 8 | C9: Arizona | D9: Princeton | E9: Princeton | F9: Arizona | G9: =if(E9=F9, "1", "0") -> 0 | H9: Arizona | I9: =if(E9=H9, "1", "0") -> 0 | J9: Arizona | K9: =if(E9=J9, "1", "0") -> 0 | L9: Arizona | M9: =if(E9=L9, "1", "0") -> 0 | N9: Arizona | O9: =if(E9=N9, "1", "0") -> 0 | P9: Arizona | Q9: =if(E9=P9, "1", "0") -> 0 | R9: Arizona | S9: =IF(R9=E9,"1","0") -> 0 | T9: Arizona | U9: =IF(T9=E9,"1","0") -> 0
A10: Round of 64 | B10: 9 | C10: Purdue | D10: FDU | E10: FDU | F10: Purdue | G10: =if(E10=F10, "1", "0") -> 0 | H10: Purdue | I10: =if(E10=H10, "1", "0") -> 0 | J10: Purdue | K10: =if(E10=J10, "1", "0") -> 0 | L10: Purdue | M10: =if(E10=L10, "1", "0") -> 0 | N10: Purdue | O10: =if(E10=N10, "1", "0") -> 0 | P10: Purdue | Q10: =if(E10=P10, "1", "0") -> 0 | R10: Purdue | S10: =IF(R10=E10,"1","0") -> 0 | T10: Purdue | U10: =IF(T10=E10,"1","0") -> 0
A11: Round of 64 | B11: 10 | C11: Memphis | D11: FAU | E11: FAU | F11: FAU | G11: =if(E11=F11, "1", "0") -> 1 | H11: FAU | I11: =if(E11=H11, "1", "0") -> 1 | J11: Memphis | K11: =if(E11=J11, "1", "0") -> 0 | L11: Memphis | M11: =if(E11=L11, "1", "0") -> 0 | N11: Memphis | O11: =if(E11=N11, "1", "0") -> 0 | P11: Memphis | Q11: =if(E11=P11, "1", "0") -> 0 | R11: FAU | S11: =IF(R11=E11,"1","0") -> 1 | T11: Memphis | U11: =IF(T11=E11,"1","0") -> 0
A12: Round of 64 | B12: 11 | C12: Duke | D12: Oral Roberts | E12: Duke | F12: Duke | G12: =if(E12=F12, "1", "0") -> 1 | H12: Duke | I12: =if(E12=H12, "1", "0") -> 1 | J12: Duke | K12: =if(E12=J12, "1", "0") -> 1 | L12: Duke | M12: =if(E12=L12, "1", "0") -> 1 | N12: Duke | O12: =if(E12=N12, "1", "0") -> 1 | P12: Duke | Q12: =if(E12=P12, "1", "0") -> 1 | R12: Duke | S12: =IF(R12=E12,"1","0") -> 1 | T12: Duke | U12: =IF(T12=E12,"1","0") -> 1
A13: Round of 64 | B13: 12 | C13: Tennessee | D13: Louisiana | E13: Tennessee | F13: Tennessee | G13: =if(E13=F13, "1", "0") -> 1 | H13: Tennessee | I13: =if(E13=H13, "1", "0") -> 1 | J13: Tennessee | K13: =if(E13=J13, "1", "0") -> 1 | L13: Tennessee | M13: =if(E13=L13, "1", "0") -> 1 | N13: Tennessee | O13: =if(E13=N13, "1", "0") -> 1 | P13: Tennessee | Q13: =if(E13=P13, "1", "0") -> 1 | R13: Tennessee | S13: =IF(R13=E13,"1","0") -> 1 | T13: Tennessee | U13: =IF(T13=E13,"1","0") -> 1
... A64: Championship | B64: 1 | C64: San Diego State | D64: UConn | E64: UConn | F64: Houston | G64: =if(E64=F64, "1", "0") -> 0 | H64: Purdue | I64: =if(E64=H64, "1", "0") -> 0 | J64: Kansas | K64: =if(E64=J64, "1", "0") -> 0 | L64: Michigan State | M64: =if(E64=L64, "1", "0") -> 0 | N64: Kansas | O64: =if(E64=N64, "1", "0") -> 0 | P64: Kansas | Q64: =if(E64=P64, "1", "0") -> 0 | R64: Kansas | S64: =IF(R64=E64,"1","0") -> 0 | T64: Marquette | U64: =IF(T64=E64,"1","0") -> 0

Sheet 2024
A1: Round | B1: Match | C1: Team1 | D1: Team2 | E1: Winner | F1: NetRankWinner | G1: NRW | H1: NetRankAdjWinner | I1: NRAW | J1: AvgOppNetWinner | K1: AONW | L1: AvgOppNetAdjWinner | M1: AONAW | N1: NetSosWinner | O1: NSW | P1: NetSosAdjWinner | Q1: NSAW | R1: WabWinner | S1: WW | T1: WabAdjWinner | U1: WAW
A2: Round of 64 | B2: 1 | C2: UConn | D2: Stetson | E2: UConn | F2: UConn | G2: =if(E2=F2, "1", "0") -> 1 | H2: UConn | I2: =if(E2=H2, "1", "0") -> 1 | J2: UConn | K2: =if(E2=J2, "1", "0") -> 1 | L2: UConn | M2: =if(E2=L2, "1", "0") -> 1 | N2: UConn | O2: =if(E2=N2, "1", "0") -> 1 | P2: UConn | Q2: =if(E2=P2, "1", "0") -> 1 | R2: UConn | S2: =if(E2=R2, "1", "0") -> 1 | T2: UConn | U2: =IF(T2=E2, "1", "0") -> 1
A3: Round of 64 | B3: 2 | C3: FAU | D3: Northwestern | E3: Northwestern | F3: FAU | G3: =if(E3=F3, "1", "0") -> 0 | H3: FAU | I3: =if(E3=H3, "1", "0") -> 0 | J3: 0rthwestern | K3: =if(E3=J3, "1", "0") -> 0 | L3: 0rthwestern | M3: =if(E3=L3, "1", "0") -> 0 | N3: 0rthwestern | O3: =if(E3=N3, "1", "0") -> 0 | P3: 0rthwestern | Q3: =if(E3=P3, "1", "0") -> 0 | R3: FAU | S3: =if(E3=R3, "1", "0") -> 0 | T3: 0rthwestern | U3: =IF(T3=E3, "1", "0") -> 0
A4: Round of 64 | B4: 3 | C4: San Diego State | D4: UAB | E4: San Diego State | F4: San Diego State | G4: =if(E4=F4, "1", "0") -> 1 | H4: San Diego State | I4: =if(E4=H4, "1", "0") -> 1 | J4: San Diego State | K4: =if(E4=J4, "1", "0") -> 1 | L4: San Diego State | M4: =if(E4=L4, "1", "0") -> 1 | N4: San Diego State | O4: =if(E4=N4, "1", "0") -> 1 | P4: San Diego State | Q4: =if(E4=P4, "1", "0") -> 1 | R4: San Diego State | S4: =if(E4=R4, "1", "0") -> 1 | T4: San Diego State | U4: =IF(T4=E4, "1", "0") -> 1
A5: Round of 64 | B5: 4 | C5: Auburn | D5: Yale | E5: Yale | F5: Auburn | G5: =if(E5=F5, "1", "0") -> 0 | H5: Auburn | I5: =if(E5=H5, "1", "0") -> 0 | J5: Auburn | K5: =if(E5=J5, "1", "0") -> 0 | L5: Auburn | M5: =if(E5=L5, "1", "0") -> 0 | N5: Auburn | O5: =if(E5=N5, "1", "0") -> 0 | P5: Auburn | Q5: =if(E5=P5, "1", "0") -> 0 | R5: Auburn | S5: =if(E5=R5, "1", "0") -> 0 | T5: Auburn | U5: =IF(T5=E5, "1", "0") -> 0
A6: Round of 64 | B6: 5 | C6: BYU | D6: Duquesne | E6: Duquesne | F6: BYU | G6: =if(E6=F6, "1", "0") -> 0 | H6: BYU | I6: =if(E6=H6, "1", "0") -> 0 | J6: BYU | K6: =if(E6=J6, "1", "0") -> 0 | L6: BYU | M6: =if(E6=L6, "1", "0") -> 0 | N6: BYU | O6: =if(E6=N6, "1", "0") -> 0 | P6: BYU | Q6: =if(E6=P6, "1", "0") -> 0 | R6: BYU | S6: =if(E6=R6, "1", "0") -> 0 | T6: BYU | U6: =IF(T6=E6, "1", "0") -> 0
A7: Round of 64 | B7: 6 | C7: IlliNois | D7: Morehead State | E7: IlliNois | F7: Illi0is | G7: =if(E7=F7, "1", "0") -> 0 | H7: Illi0is | I7: =if(E7=H7, "1", "0") -> 0 | J7: Illi0is | K7: =if(E7=J7, "1", "0") -> 0 | L7: Illi0is | M7: =if(E7=L7, "1", "0") -> 0 | N7: Illi0is | O7: =if(E7=N7, "1", "0") -> 0 | P7: Illi0is | Q7: =if(E7=P7, "1", "0") -> 0 | R7: Illi0is | S7: =if(E7=R7, "1", "0") -> 0 | T7: Illi0is | U7: =IF(T7=E7, "1", "0") -> 0
A8: Round of 64 | B8: 7 | C8: Washington State | D8: Drake | E8: Washington State | F8: Washington State | G8: =if(E8=F8, "1", "0") -> 1 | H8: Drake | I8: =if(E8=H8, "1", "0") -> 0 | J8: Washington State | K8: =if(E8=J8, "1", "0") -> 1 | L8: Washington State | M8: =if(E8=L8, "1", "0") -> 1 | N8: Washington State | O8: =if(E8=N8, "1", "0") -> 1 | P8: Washington State | Q8: =if(E8=P8, "1", "0") -> 1 | R8: Washington State | S8: =if(E8=R8, "1", "0") -> 1 | T8: Drake | U8: =IF(T8=E8, "1", "0") -> 0
A9: Round of 64 | B9: 8 | C9: Iowa State | D9: South Dakota State | E9: Iowa State | F9: Iowa State | G9: =if(E9=F9, "1", "0") -> 1 | H9: Iowa State | I9: =if(E9=H9, "1", "0") -> 1 | J9: Iowa State | K9: =if(E9=J9, "1", "0") -> 1 | L9: Iowa State | M9: =if(E9=L9, "1", "0") -> 1 | N9: Iowa State | O9: =if(E9=N9, "1", "0") -> 1 | P9: Iowa State | Q9: =if(E9=P9, "1", "0") -> 1 | R9: Iowa State | S9: =if(E9=R9, "1", "0") -> 1 | T9: Iowa State | U9: =IF(T9=E9, "1", "0") -> 1
A10: Round of 64 | B10: 9 | C10: North Carolina | D10: Wagner | E10: North Carolina | F10: 0rth Carolina | G10: =if(E10=F10, "1", "0") -> 0 | H10: 0rth Carolina | I10: =if(E10=H10, "1", "0") -> 0 | J10: 0rth Carolina | K10: =if(E10=J10, "1", "0") -> 0 | L10: 0rth Carolina | M10: =if(E10=L10, "1", "0") -> 0 | N10: 0rth Carolina | O10: =if(E10=N10, "1", "0") -> 0 | P10: 0rth Carolina | Q10: =if(E10=P10, "1", "0") -> 0 | R10: 0rth Carolina | S10: =if(E10=R10, "1", "0") -> 0 | T10: 0rth Carolina | U10: =IF(T10=E10, "1", "0") -> 0
A11: Round of 64 | B11: 10 | C11: Mississippi State | D11: Michigan State | E11: Michigan State | F11: Michigan State | G11: =if(E11=F11, "1", "0") -> 1 | H11: Mississippi State | I11: =if(E11=H11, "1", "0") -> 0 | J11: Michigan State | K11: =if(E11=J11, "1", "0") -> 1 | L11: Michigan State | M11: =if(E11=L11, "1", "0") -> 1 | N11: Michigan State | O11: =if(E11=N11, "1", "0") -> 1 | P11: Michigan State | Q11: =if(E11=P11, "1", "0") -> 1 | R11: Mississippi State | S11: =if(E11=R11, "1", "0") -> 0 | T11: Michigan State | U11: =IF(T11=E11, "1", "0") -> 1
A12: Round of 64 | B12: 11 | C12: Saint Mary's | D12: Grand Canyon | E12: Grand Canyon | F12: Saint Mary's | G12: =if(E12=F12, "1", "0") -> 0 | H12: Saint Mary's | I12: =if(E12=H12, "1", "0") -> 0 | J12: Saint Mary's | K12: =if(E12=J12, "1", "0") -> 0 | L12: Grand Canyon | M12: =if(E12=L12, "1", "0") -> 1 | N12: Saint Mary's | O12: =if(E12=N12, "1", "0") -> 0 | P12: Saint Mary's | Q12: =if(E12=P12, "1", "0") -> 0 | R12: Grand Canyon | S12: =if(E12=R12, "1", "0") -> 1 | T12: Saint Mary's | U12: =IF(T12=E12, "1", "0") -> 0
A13: Round of 64 | B13: 12 | C13: Alabama | D13: Charleston | E13: Alabama | F13: Alabama | G13: =if(E13=F13, "1", "0") -> 1 | H13: Alabama | I13: =if(E13=H13, "1", "0") -> 1 | J13: Alabama | K13: =if(E13=J13, "1", "0") -> 1 | L13: Alabama | M13: =if(E13=L13, "1", "0") -> 1 | N13: Alabama | O13: =if(E13=N13, "1", "0") -> 1 | P13: Alabama | Q13: =if(E13=P13, "1", "0") -> 1 | R13: Alabama | S13: =if(E13=R13, "1", "0") -> 1 | T13: Alabama | U13: =IF(T13=E13, "1", "0") -> 1
... A64: Championship | B64: 1 | C64: UConn | D64: Purdue | E64: UConn | F64: Houston | G64: =if(E64=F64, "1", "0") -> 0 | H64: Purdue | I64: =if(E64=H64, "1", "0") -> 0 | J64: Purdue | K64: =if(E64=J64, "1", "0") -> 0 | L64: Alabama | M64: =if(E64=L64, "1", "0") -> 0 | N64: Baylor | O64: =if(E64=N64, "1", "0") -> 0 | P64: Purdue | Q64: =if(E64=P64, "1", "0") -> 0 | R64: Purdue | S64: =if(E64=R64, "1", "0") -> 0 | T64: Illi0is | U64: =IF(T64=E64, "1", "0") -> 0

Sheet 2025
A1: Round | B1: Match | C1: Team1 | D1: Team2 | E1: Winner | F1: NetRankWinner | G1: NRW | H1: NetRankAdjWinner | I1: NRAW | J1: AvgOppNetWinner | K1: AONW | L1: AvgOppNetAdjWinner | M1: AONAW | N1: NetSosWinner | O1: NSW | P1: NetSosAdjWinner | Q1: NSAW | R1: WabWinner | S1: WW | T1: WabAdjWinner | U1: WAW
A2: Round of 64 | B2: 1 | C2: Auburn | D2: Alabama State | E2: Auburn | F2: Auburn | G2: =if(E2=F2, "1", "0") -> 1 | H2: Auburn | I2: =if(E2=H2, "1", "0") -> 1 | J2: Auburn | K2: =if(E2=J2, "1", "0") -> 1 | L2: Auburn | M2: =if(E2=L2, "1", "0") -> 1 | N2: Auburn | O2: =if(E2=N2, "1", "0") -> 1 | P2: Auburn | Q2: =if(E2=P2, "1", "0") -> 1 | R2: Auburn | S2: =if(E2=R2, "1", "0") -> 1 | T2: Auburn | U2: =if(E2=T2, "1", "0") -> 1
A3: Round of 64 | B3: 2 | C3: Louisville | D3: Creighton | E3: Creighton | F3: Louisville | G3: =if(E3=F3, "1", "0") -> 0 | H3: Louisville | I3: =if(E3=H3, "1", "0") -> 0 | J3: Louisville | K3: =if(E3=J3, "1", "0") -> 0 | L3: Creighton | M3: =if(E3=L3, "1", "0") -> 1 | N3: Creighton | O3: =if(E3=N3, "1", "0") -> 1 | P3: Louisville | Q3: =if(E3=P3, "1", "0") -> 0 | R3: Louisville | S3: =if(E3=R3, "1", "0") -> 0 | T3: Louisville | U3: =if(E3=T3, "1", "0") -> 0
A4: Round of 64 | B4: 3 | C4: Michigan | D4: San Diego State | E4: Michigan | F4: Michigan | G4: =if(E4=F4, "1", "0") -> 1 | H4: Michigan | I4: =if(E4=H4, "1", "0") -> 1 | J4: Michigan | K4: =if(E4=J4, "1", "0") -> 1 | L4: Michigan | M4: =if(E4=L4, "1", "0") -> 1 | N4: Michigan | O4: =if(E4=N4, "1", "0") -> 1 | P4: Michigan | Q4: =if(E4=P4, "1", "0") -> 1 | R4: Michigan | S4: =if(E4=R4, "1", "0") -> 1 | T4: Michigan | U4: =if(E4=T4, "1", "0") -> 1
A5: Round of 64 | B5: 4 | C5: Texas A&M | D5: Yale | E5: Texas A&M | F5: Texas A&M | G5: =if(E5=F5, "1", "0") -> 1 | H5: Texas A&M | I5: =if(E5=H5, "1", "0") -> 1 | J5: Texas A&M | K5: =if(E5=J5, "1", "0") -> 1 | L5: Texas A&M | M5: =if(E5=L5, "1", "0") -> 1 | N5: Texas A&M | O5: =if(E5=N5, "1", "0") -> 1 | P5: Texas A&M | Q5: =if(E5=P5, "1", "0") -> 1 | R5: Texas A&M | S5: =if(E5=R5, "1", "0") -> 1 | T5: Texas A&M | U5: =if(E5=T5, "1", "0") -> 1
A6: Round of 64 | B6: 5 | C6: Ole Miss | D6: North Carolina | E6: Ole Miss | F6: Ole Miss | G6: =if(E6=F6, "1", "0") -> 1 | H6: Ole Miss | I6: =if(E6=H6, "1", "0") -> 1 | J6: Ole Miss | K6: =if(E6=J6, "1", "0") -> 1 | L6: Ole Miss | M6: =if(E6=L6, "1", "0") -> 1 | N6: Ole Miss | O6: =if(E6=N6, "1", "0") -> 1 | P6: Ole Miss | Q6: =if(E6=P6, "1", "0") -> 1 | R6: Ole Miss | S6: =if(E6=R6, "1", "0") -> 1 | T6: Ole Miss | U6: =if(E6=T6, "1", "0") -> 1
A7: Round of 64 | B7: 6 | C7: Iowa State | D7: Lipscomb | E7: Iowa State | F7: Iowa State | G7: =if(E7=F7, "1", "0") -> 1 | H7: Iowa State | I7: =if(E7=H7, "1", "0") -> 1 | J7: Iowa State | K7: =if(E7=J7, "1", "0") -> 1 | L7: Iowa State | M7: =if(E7=L7, "1", "0") -> 1 | N7: Iowa State | O7: =if(E7=N7, "1", "0") -> 1 | P7: Iowa State | Q7: =if(E7=P7, "1", "0") -> 1 | R7: Iowa State | S7: =if(E7=R7, "1", "0") -> 1 | T7: Iowa State | U7: =if(E7=T7, "1", "0") -> 1
A8: Round of 64 | B8: 7 | C8: Marquette | D8: New Mexico | E8: New Mexico | F8: Marquette | G8: =if(E8=F8, "1", "0") -> 0 | H8: Marquette | I8: =if(E8=H8, "1", "0") -> 0 | J8: Marquette | K8: =if(E8=J8, "1", "0") -> 0 | L8: Marquette | M8: =if(E8=L8, "1", "0") -> 0 | N8: Marquette | O8: =if(E8=N8, "1", "0") -> 0 | P8: Marquette | Q8: =if(E8=P8, "1", "0") -> 0 | R8: Marquette | S8: =if(E8=R8, "1", "0") -> 0 | T8: New Mexico | U8: =if(E8=T8, "1", "0") -> 1
A9: Round of 64 | B9: 8 | C9: Michigan State | D9: Bryant | E9: Michigan State | F9: Michigan State | G9: =if(E9=F9, "1", "0") -> 1 | H9: Michigan State | I9: =if(E9=H9, "1", "0") -> 1 | J9: Michigan State | K9: =if(E9=J9, "1", "0") -> 1 | L9: Michigan State | M9: =if(E9=L9, "1", "0") -> 1 | N9: Michigan State | O9: =if(E9=N9, "1", "0") -> 1 | P9: Michigan State | Q9: =if(E9=P9, "1", "0") -> 1 | R9: Michigan State | S9: =if(E9=R9, "1", "0") -> 1 | T9: Michigan State | U9: =if(E9=T9, "1", "0") -> 1
A10: Round of 64 | B10: 9 | C10: Florida | D10: Norfolk State | E10: Florida | F10: Florida | G10: =if(E10=F10, "1", "0") -> 1 | H10: Florida | I10: =if(E10=H10, "1", "0") -> 1 | J10: Florida | K10: =if(E10=J10, "1", "0") -> 1 | L10: Florida | M10: =if(E10=L10, "1", "0") -> 1 | N10: Florida | O10: =if(E10=N10, "1", "0") -> 1 | P10: Florida | Q10: =if(E10=P10, "1", "0") -> 1 | R10: Florida | S10: =if(E10=R10, "1", "0") -> 1 | T10: Florida | U10: =if(E10=T10, "1", "0") -> 1
A11: Round of 64 | B11: 10 | C11: UConn | D11: Oklahoma | E11: UConn | F11: UConn | G11: =if(E11=F11, "1", "0") -> 1 | H11: UConn | I11: =if(E11=H11, "1", "0") -> 1 | J11: Oklahoma | K11: =if(E11=J11, "1", "0") -> 0 | L11: Oklahoma | M11: =if(E11=L11, "1", "0") -> 0 | N11: Oklahoma | O11: =if(E11=N11, "1", "0") -> 0 | P11: Oklahoma | Q11: =if(E11=P11, "1", "0") -> 0 | R11: Oklahoma | S11: =if(E11=R11, "1", "0") -> 0 | T11: UConn | U11: =if(E11=T11, "1", "0") -> 1
A12: Round of 64 | B12: 11 | C12: Memphis | D12: Colorado State | E12: Colorado State | F12: Colorado State | G12: =if(E12=F12, "1", "0") -> 1 | H12: Memphis | I12: =if(E12=H12, "1", "0") -> 0 | J12: Memphis | K12: =if(E12=J12, "1", "0") -> 0 | L12: Colorado State | M12: =if(E12=L12, "1", "0") -> 1 | N12: Colorado State | O12: =if(E12=N12, "1", "0") -> 1 | P12: Memphis | Q12: =if(E12=P12, "1", "0") -> 0 | R12: Memphis | S12: =if(E12=R12, "1", "0") -> 0 | T12: Memphis | U12: =if(E12=T12, "1", "0") -> 0
A13: Round of 64 | B13: 12 | C13: Maryland | D13: Grand Canyon | E13: Maryland | F13: Maryland | G13: =if(E13=F13, "1", "0") -> 1 | H13: Maryland | I13: =if(E13=H13, "1", "0") -> 1 | J13: Maryland | K13: =if(E13=J13, "1", "0") -> 1 | L13: Maryland | M13: =if(E13=L13, "1", "0") -> 1 | N13: Maryland | O13: =if(E13=N13, "1", "0") -> 1 | P13: Maryland | Q13: =if(E13=P13, "1", "0") -> 1 | R13: Maryland | S13: =if(E13=R13, "1", "0") -> 1 | T13: Maryland | U13: =if(E13=T13, "1", "0") -> 1
... A64: Championship | B64: 1 | C64: Florida | D64: Houston | E64: Florida | F64: Duke | G64: =if(E64=F64, "1", "0") -> 0 | H64: Gonzaga | I64: =if(E64=H64, "1", "0") -> 0 | J64: Alabama | K64: =if(E64=J64, "1", "0") -> 0 | L64: Texas A&M | M64: =if(E64=L64, "1", "0") -> 0 | N64: Alabama | O64: =if(E64=N64, "1", "0") -> 0 | P64: Kansas | Q64: =if(E64=P64, "1", "0") -> 0 | R64: Auburn | S64: =if(E64=R64, "1", "0") -> 0 | T64: Duke | U64: =if(E64=T64, "1", "0") -> 0

Sheet Percentages
B1: 2022 | C1: 2023 | D1: 2024 | E1: 2025 | F1: Ro64 | G1: Ro32 | H1: Sweet16 | I1: Elite8 | J1: Final4 | K1: Championship | L1: Overall | M1: Score | N1: Coefficients
A2: NetRank | B2: =(COUNTIF('2022'!G2:'2022'!G64,"1"))/63 -> 0.44444444 | C2: =(COUNTIF('2023'!G2:'2023'!G64,"1"))/63 -> 0.55555556 | D2: =(COUNTIF('2024'!G2:'2024'!G64,"1"))/63 -> 0.58730159 | E2: =(COUNTIF('2025'!G2:'2025'!G64,"1"))/63 -> 0.77777778 | F2: =((COUNTIF('2022'!G2:'2022'!G33,"1"))+(COUNTIF('2023'!G2:'2023'!G33,"1"))+(COUNTIF('2024'!G2:'2024'!G33,"1"))+(COUNTIF('2025'!G2:'2025'!G33,"1")))/128 -> 0.6875 | G2: =((COUNTIF('2022'!G34:'2022'!G49,"1"))+(COUNTIF('2023'!G34:'2023'!G49,"1"))+(COUNTIF('2024'!G34:'2024'!G49,"1"))+(COUNTIF('2025'!G34:'2025'!G49,"1")))/64 -> 0.625 | H2: =((COUNTIF('2022'!G50:'2022'!G57,"1"))+(COUNTIF('2023'!G50:'2023'!G57,"1"))+(COUNTIF('2024'!G50:'2024'!G57,"1"))+(COUNTIF('2025'!G50:'2025'!G57,"1")))/32 -> 0.40625 | I2: =((COUNTIF('2022'!G58:'2022'!G61,"1"))+(COUNTIF('2023'!G58:'2023'!G61,"1"))+(COUNTIF('2024'!G58:'2024'!G61,"1"))+(COUNTIF('2025'!G58:'2025'!G61,"1")))/16 -> 0.4375 | J2: =((COUNTIF('2022'!G62:'2022'!G63,"1"))+(COUNTIF('2023'!G62:'2023'!G63,"1"))+(COUNTIF('2024'!G62:'2024'!G63,"1"))+(COUNTIF('2025'!G62:'2025'!G63,"1")))/8 -> 0.125 | K2: =((COUNTIF('2022'!G64,"1"))+(COUNTIF('2023'!G64,"1"))+(COUNTIF('2024'!G64,"1"))+(COUNTIF('2025'!G64,"1")))/4 -> 0 | L2: =((COUNTIF('2022'!G2:'2022'!G64,"1"))+(COUNTIF('2023'!G2:'2023'!G64,"1"))+(COUNTIF('2024'!G2:'2024'!G64,"1"))+(COUNTIF('2025'!G2:'2025'!G64,"1")))/252 -> 0.59126984 | M2: =(((((COUNTIF('2022'!G2:'2022'!G33,"1"))+(COUNTIF('2023'!G2:'2023'!G33,"1"))+(COUNTIF('2024'!G2:'2024'!G33,"1"))+(COUNTIF('2025'!G2:'2025'!G33,"1")))*10)+(((COUNTIF('2022'!G34:'2022'!G49,"1"))+(COUNTIF('2023'!G34:'2023'!G49,"1"))+(COUNTIF('2024'!G34:'2024'!G49,"1"))+(COUNTIF('2025'!G34:'2025'!G49,"1")))*20)+((((COUNTIF('2022'!G50:'2022'!G57,"1"))+(COUNTIF('2023'!G50:'2023'!G57,"1"))+(COUNTIF('2024'!G50:'2024'!G57,"1"))+(COUNTIF('2025'!G50:'2025'!G57,"1")))*40)+(((COUNTIF('2022'!G58:'2022'!G61,"1"))+(COUNTIF('2023'!G58:'2023'!G61,"1"))+(COUNTIF('2024'!G58:'2024'!G61,"1"))+(COUNTIF('2025'!G58:'2025'!G61,"1")))*80)+(((COUNTIF('2022'!G62:'2022'!G63,"1"))+(COUNTIF('2023'!G62:'2023'!G63,"1"))+(COUNTIF('2024'!G62:'2024'!G63,"1"))+(COUNTIF('2025'!G62:'2025'!G63,"1")))*160)+(((COUNTIF('2022'!G64,"1"))+(COUNTIF('2023'!G64,"1"))+(COUNTIF('2024'!G64,"1"))+(COUNTIF('2025'!G64,"1")))*320))))/4 -> 730 | N2: =M2/5447.5 -> 0.13400643
A3: NetRankAdj | B3: =(COUNTIF('2022'!I2:'2022'!I64,"1"))/63 -> 0.52380952 | C3: =(COUNTIF('2023'!I2:'2023'!I64,"1"))/63 -> 0.55555556 | D3: =(COUNTIF('2024'!I2:'2024'!I64,"1"))/63 -> 0.49206349 | E3: =(COUNTIF('2025'!I2:'2025'!I64,"1"))/63 -> 0.66666667 | F3: =((COUNTIF('2022'!I2:'2022'!I33,"1"))+(COUNTIF('2023'!I2:'2023'!I33,"1"))+(COUNTIF('2024'!I2:'2024'!I33,"1"))+(COUNTIF('2025'!I2:'2025'!I33,"1")))/128 -> 0.640625 | G3: =((COUNTIF('2022'!I34:'2022'!I49,"1"))+(COUNTIF('2023'!I34:'2023'!I49,"1"))+(COUNTIF('2024'!I34:'2024'!I49,"1"))+(COUNTIF('2025'!I34:'2025'!I49,"1")))/64 -> 0.59375 | H3: =((COUNTIF('2022'!I50:'2022'!I57,"1"))+(COUNTIF('2023'!I50:'2023'!I57,"1"))+(COUNTIF('2024'!I50:'2024'!I57,"1"))+(COUNTIF('2025'!I50:'2025'!I57,"1")))/32 -> 0.4375 | I3: =((COUNTIF('2022'!I58:'2022'!I61,"1"))+(COUNTIF('2023'!I58:'2023'!I61,"1"))+(COUNTIF('2024'!I58:'2024'!I61,"1"))+(COUNTIF('2025'!I58:'2025'!I61,"1")))/16 -> 0.25 | J3: =((COUNTIF('2022'!I62:'2022'!I63,"1"))+(COUNTIF('2023'!I62:'2023'!I63,"1"))+(COUNTIF('2024'!I62:'2024'!I63,"1"))+(COUNTIF('2025'!I62:'2025'!I63,"1")))/8 -> 0.25 | K3: =((COUNTIF('2022'!I64,"1"))+(COUNTIF('2023'!I64,"1"))+(COUNTIF('2024'!I64,"1"))+(COUNTIF('2025'!I64,"1")))/4 -> 0.25 | L3: =((COUNTIF('2022'!I2:'2022'!I64,"1"))+(COUNTIF('2023'!I2:'2023'!I64,"1"))+(COUNTIF('2024'!I2:'2024'!I64,"1"))+(COUNTIF('2025'!I2:'2025'!I64,"1")))/252 -> 0.55952381 | M3: =(((((COUNTIF('2022'!I2:'2022'!I33,"1"))+(COUNTIF('2023'!I2:'2023'!I33,"1"))+(COUNTIF('2024'!I2:'2024'!I33,"1"))+(COUNTIF('2025'!I2:'2025'!I33,"1")))*10)+(((COUNTIF('2022'!I34:'2022'!I49,"1"))+(COUNTIF('2023'!I34:'2023'!I49,"1"))+(COUNTIF('2024'!I34:'2024'!I49,"1"))+(COUNTIF('2025'!I34:'2025'!I49,"1")))*20)+((((COUNTIF('2022'!I50:'2022'!I57,"1"))+(COUNTIF('2023'!I50:'2023'!I57,"1"))+(COUNTIF('2024'!I50:'2024'!I57,"1"))+(COUNTIF('2025'!I50:'2025'!I57,"1")))*40)+(((COUNTIF('2022'!I58:'2022'!I61,"1"))+(COUNTIF('2023'!I58:'2023'!I61,"1"))+(COUNTIF('2024'!I58:'2024'!I61,"1"))+(COUNTIF('2025'!I58:'2025'!I61,"1")))*80)+(((COUNTIF('2022'!I62:'2022'!I63,"1"))+(COUNTIF('2023'!I62:'2023'!I63,"1"))+(COUNTIF('2024'!I62:'2024'!I63,"1"))+(COUNTIF('2025'!I62:'2025'!I63,"1")))*160)+(((COUNTIF('2022'!I64,"1"))+(COUNTIF('2023'!I64,"1"))+(COUNTIF('2024'!I64,"1"))+(COUNTIF('2025'!I64,"1")))*320))))/4 -> 775 | N3: =M3/5447.5 -> 0.1422671
A4: AvgOppNet | B4: =(COUNTIF('2022'!K2:'2022'!K64,"1"))/63 -> 0.47619048 | C4: =(COUNTIF('2023'!K2:'2023'!K64,"1"))/63 -> 0.47619048 | D4: =(COUNTIF('2024'!K2:'2024'!K64,"1"))/63 -> 0.55555556 | E4: =(COUNTIF('2025'!K2:'2025'!K64,"1"))/63 -> 0.63492063 | F4: =((COUNTIF('2022'!K2:'2022'!K33,"1"))+(COUNTIF('2023'!K2:'2023'!K33,"1"))+(COUNTIF('2024'!K2:'2024'!K33,"1"))+(COUNTIF('2025'!K2:'2025'!K33,"1")))/128 -> 0.6875 | G4: =((COUNTIF('2022'!K34:'2022'!K49,"1"))+(COUNTIF('2023'!K34:'2023'!K49,"1"))+(COUNTIF('2024'!K34:'2024'!K49,"1"))+(COUNTIF('2025'!K34:'2025'!K49,"1")))/64 -> 0.484375 | H4: =((COUNTIF('2022'!K50:'2022'!K57,"1"))+(COUNTIF('2023'!K50:'2023'!K57,"1"))+(COUNTIF('2024'!K50:'2024'!K57,"1"))+(COUNTIF('2025'!K50:'2025'!K57,"1")))/32 -> 0.3125 | I4: =((COUNTIF('2022'!K58:'2022'!K61,"1"))+(COUNTIF('2023'!K58:'2023'!K61,"1"))+(COUNTIF('2024'!K58:'2024'!K61,"1"))+(COUNTIF('2025'!K58:'2025'!K61,"1")))/16 -> 0.25 | J4: =((COUNTIF('2022'!K62:'2022'!K63,"1"))+(COUNTIF('2023'!K62:'2023'!K63,"1"))+(COUNTIF('2024'!K62:'2024'!K63,"1"))+(COUNTIF('2025'!K62:'2025'!K63,"1")))/8 -> 0.25 | K4: =((COUNTIF('2022'!K64,"1"))+(COUNTIF('2023'!K64,"1"))+(COUNTIF('2024'!K64,"1"))+(COUNTIF('2025'!K64,"1")))/4 -> 0 | L4: =((COUNTIF('2022'!K2:'2022'!K64,"1"))+(COUNTIF('2023'!K2:'2023'!K64,"1"))+(COUNTIF('2024'!K2:'2024'!K64,"1"))+(COUNTIF('2025'!K2:'2025'!K64,"1")))/252 -> 0.53571429 | M4: =(((((COUNTIF('2022'!K2:'2022'!K33,"1"))+(COUNTIF('2023'!K2:'2023'!K33,"1"))+(COUNTIF('2024'!K2:'2024'!K33,"1"))+(COUNTIF('2025'!K2:'2025'!K33,"1")))*10)+(((COUNTIF('2022'!K34:'2022'!K49,"1"))+(COUNTIF('2023'!K34:'2023'!K49,"1"))+(COUNTIF('2024'!K34:'2024'!K49,"1"))+(COUNTIF('2025'!K34:'2025'!K49,"1")))*20)+((((COUNTIF('2022'!K50:'2022'!K57,"1"))+(COUNTIF('2023'!K50:'2023'!K57,"1"))+(COUNTIF('2024'!K50:'2024'!K57,"1"))+(COUNTIF('2025'!K50:'2025'!K57,"1")))*40)+(((COUNTIF('2022'!K58:'2022'!K61,"1"))+(COUNTIF('2023'!K58:'2023'!K61,"1"))+(COUNTIF('2024'!K58:'2024'!K61,"1"))+(COUNTIF('2025'!K58:'2025'!K61,"1")))*80)+(((COUNTIF('2022'!K62:'2022'!K63,"1"))+(COUNTIF('2023'!K62:'2023'!K63,"1"))+(COUNTIF('2024'!K62:'2024'!K63,"1"))+(COUNTIF('2025'!K62:'2025'!K63,"1")))*160)+(((COUNTIF('2022'!K64,"1"))+(COUNTIF('2023'!K64,"1"))+(COUNTIF('2024'!K64,"1"))+(COUNTIF('2025'!K64,"1")))*320))))/4 -> 635 | N4: =M4/5447.5 -> 0.11656723
A5: AvgOppNetAdj | B5: =(COUNTIF('2022'!M2:'2022'!M64,"1"))/63 -> 0.46031746 | C5: =(COUNTIF('2023'!M2:'2023'!M64,"1"))/63 -> 0.55555556 | D5: =(COUNTIF('2024'!M2:'2024'!M64,"1"))/63 -> 0.53968254 | E5: =(COUNTIF('2025'!M2:'2025'!M64,"1"))/63 -> 0.58730159 | F5: =((COUNTIF('2022'!M2:'2022'!M33,"1"))+(COUNTIF('2023'!M2:'2023'!M33,"1"))+(COUNTIF('2024'!M2:'2024'!M33,"1"))+(COUNTIF('2025'!M2:'2025'!M33,"1")))/128 -> 0.71875 | G5: =((COUNTIF('2022'!M34:'2022'!M49,"1"))+(COUNTIF('2023'!M34:'2023'!M49,"1"))+(COUNTIF('2024'!M34:'2024'!M49,"1"))+(COUNTIF('2025'!M34:'2025'!M49,"1")))/64 -> 0.515625 | H5: =((COUNTIF('2022'!M50:'2022'!M57,"1"))+(COUNTIF('2023'!M50:'2023'!M57,"1"))+(COUNTIF('2024'!M50:'2024'!M57,"1"))+(COUNTIF('2025'!M50:'2025'!M57,"1")))/32 -> 0.25 | I5: =((COUNTIF('2022'!M58:'2022'!M61,"1"))+(COUNTIF('2023'!M58:'2023'!M61,"1"))+(COUNTIF('2024'!M58:'2024'!M61,"1"))+(COUNTIF('2025'!M58:'2025'!M61,"1")))/16 -> 0.125 | J5: =((COUNTIF('2022'!M62:'2022'!M63,"1"))+(COUNTIF('2023'!M62:'2023'!M63,"1"))+(COUNTIF('2024'!M62:'2024'!M63,"1"))+(COUNTIF('2025'!M62:'2025'!M63,"1")))/8 -> 0 | K5: =((COUNTIF('2022'!M64,"1"))+(COUNTIF('2023'!M64,"1"))+(COUNTIF('2024'!M64,"1"))+(COUNTIF('2025'!M64,"1")))/4 -> 0 | L5: =((COUNTIF('2022'!M2:'2022'!M64,"1"))+(COUNTIF('2023'!M2:'2023'!M64,"1"))+(COUNTIF('2024'!M2:'2024'!M64,"1"))+(COUNTIF('2025'!M2:'2025'!M64,"1")))/252 -> 0.53571429 | M5: =(((((COUNTIF('2022'!M2:'2022'!M33,"1"))+(COUNTIF('2023'!M2:'2023'!M33,"1"))+(COUNTIF('2024'!M2:'2024'!M33,"1"))+(COUNTIF('2025'!M2:'2025'!M33,"1")))*10)+(((COUNTIF('2022'!M34:'2022'!M49,"1"))+(COUNTIF('2023'!M34:'2023'!M49,"1"))+(COUNTIF('2024'!M34:'2024'!M49,"1"))+(COUNTIF('2025'!M34:'2025'!M49,"1")))*20)+((((COUNTIF('2022'!M50:'2022'!M57,"1"))+(COUNTIF('2023'!M50:'2023'!M57,"1"))+(COUNTIF('2024'!M50:'2024'!M57,"1"))+(COUNTIF('2025'!M50:'2025'!M57,"1")))*40)+(((COUNTIF('2022'!M58:'2022'!M61,"1"))+(COUNTIF('2023'!M58:'2023'!M61,"1"))+(COUNTIF('2024'!M58:'2024'!M61,"1"))+(COUNTIF('2025'!M58:'2025'!M61,"1")))*80)+(((COUNTIF('2022'!M62:'2022'!M63,"1"))+(COUNTIF('2023'!M62:'2023'!M63,"1"))+(COUNTIF('2024'!M62:'2024'!M63,"1"))+(COUNTIF('2025'!M62:'2025'!M63,"1")))*160)+(((COUNTIF('2022'!M64,"1"))+(COUNTIF('2023'!M64,"1"))+(COUNTIF('2024'!M64,"1"))+(COUNTIF('2025'!M64,"1")))*320))))/4 -> 515 | N5: =M5/5447.5 -> 0.094538779
A6: NetSos | B6: =(COUNTIF('2022'!O2:'2022'!O64,"1"))/63 -> 0.44444444 | C6: =(COUNTIF('2023'!O2:'2023'!O64,"1"))/63 -> 0.49206349 | D6: =(COUNTIF('2024'!O2:'2024'!O64,"1"))/63 -> 0.50793651 | E6: =(COUNTIF('2025'!O2:'2025'!O64,"1"))/63 -> 0.57142857 | F6: =((COUNTIF('2022'!O2:'2022'!O33,"1"))+(COUNTIF('2023'!O2:'2023'!O33,"1"))+(COUNTIF('2024'!O2:'2024'!O33,"1"))+(COUNTIF('2025'!O2:'2025'!O33,"1")))/128 -> 0.7109375 | G6: =((COUNTIF('2022'!O34:'2022'!O49,"1"))+(COUNTIF('2023'!O34:'2023'!O49,"1"))+(COUNTIF('2024'!O34:'2024'!O49,"1"))+(COUNTIF('2025'!O34:'2025'!O49,"1")))/64 -> 0.4375 | H6: =((COUNTIF('2022'!O50:'2022'!O57,"1"))+(COUNTIF('2023'!O50:'2023'!O57,"1"))+(COUNTIF('2024'!O50:'2024'!O57,"1"))+(COUNTIF('2025'!O50:'2025'!O57,"1")))/32 -> 0.1875 | I6: =((COUNTIF('2022'!O58:'2022'!O61,"1"))+(COUNTIF('2023'!O58:'2023'!O61,"1"))+(COUNTIF('2024'!O58:'2024'!O61,"1"))+(COUNTIF('2025'!O58:'2025'!O61,"1")))/16 -> 0.125 | J6: =((COUNTIF('2022'!O62:'2022'!O63,"1"))+(COUNTIF('2023'!O62:'2023'!O63,"1"))+(COUNTIF('2024'!O62:'2024'!O63,"1"))+(COUNTIF('2025'!O62:'2025'!O63,"1")))/8 -> 0 | K6: =((COUNTIF('2022'!O64,"1"))+(COUNTIF('2023'!O64,"1"))+(COUNTIF('2024'!O64,"1"))+(COUNTIF('2025'!O64,"1")))/4 -> 0 | L6: =((COUNTIF('2022'!O2:'2022'!O64,"1"))+(COUNTIF('2023'!O2:'2023'!O64,"1"))+(COUNTIF('2024'!O2:'2024'!O64,"1"))+(COUNTIF('2025'!O2:'2025'!O64,"1")))/252 -> 0.50396825 | M6: =(((((COUNTIF('2022'!O2:'2022'!O33,"1"))+(COUNTIF('2023'!O2:'2023'!O33,"1"))+(COUNTIF('2024'!O2:'2024'!O33,"1"))+(COUNTIF('2025'!O2:'2025'!O33,"1")))*10)+(((COUNTIF('2022'!O34:'2022'!O49,"1"))+(COUNTIF('2023'!O34:'2023'!O49,"1"))+(COUNTIF('2024'!O34:'2024'!O49,"1"))+(COUNTIF('2025'!O34:'2025'!O49,"1")))*20)+((((COUNTIF('2022'!O50:'2022'!O57,"1"))+(COUNTIF('2023'!O50:'2023'!O57,"1"))+(COUNTIF('2024'!O50:'2024'!O57,"1"))+(COUNTIF('2025'!O50:'2025'!O57,"1")))*40)+(((COUNTIF('2022'!O58:'2022'!O61,"1"))+(COUNTIF('2023'!O58:'2023'!O61,"1"))+(COUNTIF('2024'!O58:'2024'!O61,"1"))+(COUNTIF('2025'!O58:'2025'!O61,"1")))*80)+(((COUNTIF('2022'!O62:'2022'!O63,"1"))+(COUNTIF('2023'!O62:'2023'!O63,"1"))+(COUNTIF('2024'!O62:'2024'!O63,"1"))+(COUNTIF('2025'!O62:'2025'!O63,"1")))*160)+(((COUNTIF('2022'!O64,"1"))+(COUNTIF('2023'!O64,"1"))+(COUNTIF('2024'!O64,"1"))+(COUNTIF('2025'!O64,"1")))*320))))/4 -> 467.5 | N6: =M6/5447.5 -> 0.085819183
A7: NetSosAdj | B7: =(COUNTIF('2022'!Q2:'2022'!Q64,"1"))/63 -> 0.47619048 | C7: =(COUNTIF('2023'!Q2:'2023'!Q64,"1"))/63 -> 0.53968254 | D7: =(COUNTIF('2024'!Q2:'2024'!Q64,"1"))/63 -> 0.50793651 | E7: =(COUNTIF('2025'!Q2:'2025'!Q64,"1"))/63 -> 0.50793651 | F7: =((COUNTIF('2022'!Q2:'2022'!Q33,"1"))+(COUNTIF('2023'!Q2:'2023'!Q33,"1"))+(COUNTIF('2024'!Q2:'2024'!Q33,"1"))+(COUNTIF('2025'!Q2:'2025'!Q33,"1")))/128 -> 0.6875 | G7: =((COUNTIF('2022'!Q34:'2022'!Q49,"1"))+(COUNTIF('2023'!Q34:'2023'!Q49,"1"))+(COUNTIF('2024'!Q34:'2024'!Q49,"1"))+(COUNTIF('2025'!Q34:'2025'!Q49,"1")))/64 -> 0.5 | H7: =((COUNTIF('2022'!Q50:'2022'!Q57,"1"))+(COUNTIF('2023'!Q50:'2023'!Q57,"1"))+(COUNTIF('2024'!Q50:'2024'!Q57,"1"))+(COUNTIF('2025'!Q50:'2025'!Q57,"1")))/32 -> 0.1875 | I7: =((COUNTIF('2022'!Q58:'2022'!Q61,"1"))+(COUNTIF('2023'!Q58:'2023'!Q61,"1"))+(COUNTIF('2024'!Q58:'2024'!Q61,"1"))+(COUNTIF('2025'!Q58:'2025'!Q61,"1")))/16 -> 0.0625 | J7: =((COUNTIF('2022'!Q62:'2022'!Q63,"1"))+(COUNTIF('2023'!Q62:'2023'!Q63,"1"))+(COUNTIF('2024'!Q62:'2024'!Q63,"1"))+(COUNTIF('2025'!Q62:'2025'!Q63,"1")))/8 -> 0.125 | K7: =((COUNTIF('2022'!Q64,"1"))+(COUNTIF('2023'!Q64,"1"))+(COUNTIF('2024'!Q64,"1"))+(COUNTIF('2025'!Q64,"1")))/4 -> 0 | L7: =((COUNTIF('2022'!Q2:'2022'!Q64,"1"))+(COUNTIF('2023'!Q2:'2023'!Q64,"1"))+(COUNTIF('2024'!Q2:'2024'!Q64,"1"))+(COUNTIF('2025'!Q2:'2025'!Q64,"1")))/252 -> 0.50793651 | M7: =(((((COUNTIF('2022'!Q2:'2022'!Q33,"1"))+(COUNTIF('2023'!Q2:'2023'!Q33,"1"))+(COUNTIF('2024'!Q2:'2024'!Q33,"1"))+(COUNTIF('2025'!Q2:'2025'!Q33,"1")))*10)+(((COUNTIF('2022'!Q34:'2022'!Q49,"1"))+(COUNTIF('2023'!Q34:'2023'!Q49,"1"))+(COUNTIF('2024'!Q34:'2024'!Q49,"1"))+(COUNTIF('2025'!Q34:'2025'!Q49,"1")))*20)+((((COUNTIF('2022'!Q50:'2022'!Q57,"1"))+(COUNTIF('2023'!Q50:'2023'!Q57,"1"))+(COUNTIF('2024'!Q50:'2024'!Q57,"1"))+(COUNTIF('2025'!Q50:'2025'!Q57,"1")))*40)+(((COUNTIF('2022'!Q58:'2022'!Q61,"1"))+(COUNTIF('2023'!Q58:'2023'!Q61,"1"))+(COUNTIF('2024'!Q58:'2024'!Q61,"1"))+(COUNTIF('2025'!Q58:'2025'!Q61,"1")))*80)+(((COUNTIF('2022'!Q62:'2022'!Q63,"1"))+(COUNTIF('2023'!Q62:'2023'!Q63,"1"))+(COUNTIF('2024'!Q62:'2024'!Q63,"1"))+(COUNTIF('2025'!Q62:'2025'!Q63,"1")))*160)+(((COUNTIF('2022'!Q64,"1"))+(COUNTIF('2023'!Q64,"1"))+(COUNTIF('2024'!Q64,"1"))+(COUNTIF('2025'!Q64,"1")))*320))))/4 -> 500 | N7: =M7/5447.5 -> 0.091785223
A8: Wab | B8: =(COUNTIF('2022'!S2:'2022'!S64,"1"))/63 -> 0.55555556 | C8: =(COUNTIF('2023'!S2:'2023'!S64,"1"))/63 -> 0.53968254 | D8: =(COUNTIF('2024'!S2:'2024'!S64,"1"))/63 -> 0.52380952 | E8: =(COUNTIF('2025'!S2:'2025'!S64,"1"))/63 -> 0.73015873 | F8: =((COUNTIF('2022'!S2:'2022'!S33,"1"))+(COUNTIF('2023'!S2:'2023'!S33,"1"))+(COUNTIF('2024'!S2:'2024'!S33,"1"))+(COUNTIF('2025'!S2:'2025'!S33,"1")))/128 -> 0.6328125 | G8: =((COUNTIF('2022'!S34:'2022'!S49,"1"))+(COUNTIF('2023'!S34:'2023'!S49,"1"))+(COUNTIF('2024'!S34:'2024'!S49,"1"))+(COUNTIF('2025'!S34:'2025'!S49,"1")))/64 -> 0.671875 | H8: =((COUNTIF('2022'!S50:'2022'!S57,"1"))+(COUNTIF('2023'!S50:'2023'!S57,"1"))+(COUNTIF('2024'!S50:'2024'!S57,"1"))+(COUNTIF('2025'!S50:'2025'!S57,"1")))/32 -> 0.40625 | I8: =((COUNTIF('2022'!S58:'2022'!S61,"1"))+(COUNTIF('2023'!S58:'2023'!S61,"1"))+(COUNTIF('2024'!S58:'2024'!S61,"1"))+(COUNTIF('2025'!S58:'2025'!S61,"1")))/16 -> 0.375 | J8: =((COUNTIF('2022'!S62:'2022'!S63,"1"))+(COUNTIF('2023'!S62:'2023'!S63,"1"))+(COUNTIF('2024'!S62:'2024'!S63,"1"))+(COUNTIF('2025'!S62:'2025'!S63,"1")))/8 -> 0.5 | K8: =((COUNTIF('2022'!S64,"1"))+(COUNTIF('2023'!S64,"1"))+(COUNTIF('2024'!S64,"1"))+(COUNTIF('2025'!S64,"1")))/4 -> 0.25 | L8: =((COUNTIF('2022'!S2:'2022'!S64,"1"))+(COUNTIF('2023'!S2:'2023'!S64,"1"))+(COUNTIF('2024'!S2:'2024'!S64,"1"))+(COUNTIF('2025'!S2:'2025'!S64,"1")))/252 -> 0.58730159 | M8: =(((((COUNTIF('2022'!S2:'2022'!S33,"1"))+(COUNTIF('2023'!S2:'2023'!S33,"1"))+(COUNTIF('2024'!S2:'2024'!S33,"1"))+(COUNTIF('2025'!S2:'2025'!S33,"1")))*10)+(((COUNTIF('2022'!S34:'2022'!S49,"1"))+(COUNTIF('2023'!S34:'2023'!S49,"1"))+(COUNTIF('2024'!S34:'2024'!S49,"1"))+(COUNTIF('2025'!S34:'2025'!S49,"1")))*20)+((((COUNTIF('2022'!S50:'2022'!S57,"1"))+(COUNTIF('2023'!S50:'2023'!S57,"1"))+(COUNTIF('2024'!S50:'2024'!S57,"1"))+(COUNTIF('2025'!S50:'2025'!S57,"1")))*40)+(((COUNTIF('2022'!S58:'2022'!S61,"1"))+(COUNTIF('2023'!S58:'2023'!S61,"1"))+(COUNTIF('2024'!S58:'2024'!S61,"1"))+(COUNTIF('2025'!S58:'2025'!S61,"1")))*80)+(((COUNTIF('2022'!S62:'2022'!S63,"1"))+(COUNTIF('2023'!S62:'2023'!S63,"1"))+(COUNTIF('2024'!S62:'2024'!S63,"1"))+(COUNTIF('2025'!S62:'2025'!S63,"1")))*160)+(((COUNTIF('2022'!S64,"1"))+(COUNTIF('2023'!S64,"1"))+(COUNTIF('2024'!S64,"1"))+(COUNTIF('2025'!S64,"1")))*320))))/4 -> 907.5 | N8: =M8/5447.5 -> 0.16659018
A9: WabAdj | B9: =(COUNTIF('2022'!U2:'2022'!U64,"1"))/63 -> 0.44444444 | C9: =(COUNTIF('2023'!U2:'2023'!U64,"1"))/63 -> 0.49206349 | D9: =(COUNTIF('2024'!U2:'2024'!U64,"1"))/63 -> 0.47619048 | E9: =(COUNTIF('2025'!U2:'2025'!U64,"1"))/63 -> 0.73015873 | F9: =((COUNTIF('2022'!U2:'2022'!U33,"1"))+(COUNTIF('2023'!U2:'2023'!U33,"1"))+(COUNTIF('2024'!U2:'2024'!U33,"1"))+(COUNTIF('2025'!U2:'2025'!U33,"1")))/128 -> 0.65625 | G9: =((COUNTIF('2022'!U34:'2022'!U49,"1"))+(COUNTIF('2023'!U34:'2023'!U49,"1"))+(COUNTIF('2024'!U34:'2024'!U49,"1"))+(COUNTIF('2025'!U34:'2025'!U49,"1")))/64 -> 0.546875 | H9: =((COUNTIF('2022'!U50:'2022'!U57,"1"))+(COUNTIF('2023'!U50:'2023'!U57,"1"))+(COUNTIF('2024'!U50:'2024'!U57,"1"))+(COUNTIF('2025'!U50:'2025'!U57,"1")))/32 -> 0.3125 | I9: =((COUNTIF('2022'!U58:'2022'!U61,"1"))+(COUNTIF('2023'!U58:'2023'!U61,"1"))+(COUNTIF('2024'!U58:'2024'!U61,"1"))+(COUNTIF('2025'!U58:'2025'!U61,"1")))/16 -> 0.3125 | J9: =((COUNTIF('2022'!U62:'2022'!U63,"1"))+(COUNTIF('2023'!U62:'2023'!U63,"1"))+(COUNTIF('2024'!U62:'2024'!U63,"1"))+(COUNTIF('2025'!U62:'2025'!U63,"1")))/8 -> 0.125 | K9: =((COUNTIF('2022'!U64,"1"))+(COUNTIF('2023'!U64,"1"))+(COUNTIF('2024'!U64,"1"))+(COUNTIF('2025'!U64,"1")))/4 -> 0 | L9: =((COUNTIF('2022'!U2:'2022'!U64,"1"))+(COUNTIF('2023'!U2:'2023'!U64,"1"))+(COUNTIF('2024'!U2:'2024'!U64,"1"))+(COUNTIF('2025'!U2:'2025'!U64,"1")))/252 -> 0.53571429 | M9: =(((((COUNTIF('2022'!U2:'2022'!U33,"1"))+(COUNTIF('2023'!U2:'2023'!U33,"1"))+(COUNTIF('2024'!U2:'2024'!U33,"1"))+(COUNTIF('2025'!U2:'2025'!U33,"1")))*10)+(((COUNTIF('2022'!U34:'2022'!U49,"1"))+(COUNTIF('2023'!U34:'2023'!U49,"1"))+(COUNTIF('2024'!U34:'2024'!U49,"1"))+(COUNTIF('2025'!U34:'2025'!U49,"1")))*20)+((((COUNTIF('2022'!U50:'2022'!U57,"1"))+(COUNTIF('2023'!U50:'2023'!U57,"1"))+(COUNTIF('2024'!U50:'2024'!U57,"1"))+(COUNTIF('2025'!U50:'2025'!U57,"1")))*40)+(((COUNTIF('2022'!U58:'2022'!U61,"1"))+(COUNTIF('2023'!U58:'2023'!U61,"1"))+(COUNTIF('2024'!U58:'2024'!U61,"1"))+(COUNTIF('2025'!U58:'2025'!U61,"1")))*80)+(((COUNTIF('2022'!U62:'2022'!U63,"1"))+(COUNTIF('2023'!U62:'2023'!U63,"1"))+(COUNTIF('2024'!U62:'2024'!U63,"1"))+(COUNTIF('2025'!U62:'2025'!U63,"1")))*160)+(((COUNTIF('2022'!U64,"1"))+(COUNTIF('2023'!U64,"1"))+(COUNTIF('2024'!U64,"1"))+(COUNTIF('2025'!U64,"1")))*320))))/4 -> 625 | N9: =M9/5447.5 -> 0.11473153
A10: Averages | B10: =average(B2:B9) -> 0.4781746 | C10: =average(C2:C9) -> 0.52579365 | D10: =average(D2:D9) -> 0.52380952 | E10: =average(E2:E9) -> 0.65079365 | F10: =average(F2:F9) -> 0.67773438 | G10: =average(G2:G9) -> 0.546875 | H10: =average(H2:H9) -> 0.3125 | I10: =average(I2:I9) -> 0.2421875 | ... K10: =average(K2:K9) -> 0.0625 | L10: =AVERAGE(L2:L9) -> 0.54464286

Sheet Wab2024
A1: Rk | B1: Team | C1: NetRtg | D1: ORtg | E1: DRtg | F1: AvgWin | G1: BubbleWin | H1: Wins | I1: Wab
A2: 3 | B2: Purdue 1 | C2: =+30.62 -> 30.62 | D2: 125.2 | E2: 94.6 | F2: =D2^10/(D2^10+E2^10) -> 0.94281346 | G2: =(0.8267556358-0.8267556358*F2)/(0.8267556358+F2-2*0.8267556358*F2) -> 0.22448059 | H2: 29 | I2: 10.584933
A3: 1 | B3: Connecticut 1 | C3: =+36.43 -> 36.43 | D3: 127.5 | E3: 91.1 | F3: =D3^10/(D3^10+E3^10) -> 0.96648218 | G3: =(0.8267556358-0.8267556358*F3)/(0.8267556358+F3-2*0.8267556358*F3) -> 0.1419997 | H3: 31 | I3: 10.383272
A4: 2 | B4: Houston 1 | C4: =+31.17 -> 31.17 | D4: 118.9 | E4: 87.7 | F4: =D4^10/(D4^10+E4^10) -> 0.95450581 | G4: =(0.8267556358-0.8267556358*F4)/(0.8267556358+F4-2*0.8267556358*F4) -> 0.18530616 | H4: 30 | I4: 9.7900153
A5: 9 | B5: North Carolina 1 | C5: =+26.19 -> 26.19 | D5: 119.7 | E5: 93.5 | F5: =D5^10/(D5^10+E5^10) -> 0.9220313 | G5: =(0.8267556358-0.8267556358*F5)/(0.8267556358+F5-2*0.8267556358*F5) -> 0.28751871 | H5: 27 | I5: 6.83448
A6: 8 | B6: Iowa St. 2 | C6: =+26.47 -> 26.47 | D6: 113.9 | E6: 87.5 | F6: =D6^10/(D6^10+E6^10) -> 0.93319403 | G6: =(0.8267556358-0.8267556358*F6)/(0.8267556358+F6-2*0.8267556358*F6) -> 0.25464035 | H6: 27 | I6: 6.1957592
A7: 13 | B7: Marquette 2 | C7: =+23.02 -> 23.02 | D7: 118.2 | E7: 95.2 | F7: =D7^10/(D7^10+E7^10) -> 0.8969681 | G7: =(0.8267556358-0.8267556358*F7)/(0.8267556358+F7-2*0.8267556358*F7) -> 0.35407479 | H7: 25 | I7: 6.0697749
A8: 10 | B8: IlliNois 3 | C8: =+24.53 -> 24.53 | D8: 125.5 | E8: 101 | F8: =D8^10/(D8^10+E8^10) -> 0.89769322 | G8: =(0.8267556358-0.8267556358*F8)/(0.8267556358+F8-2*0.8267556358*F8) -> 0.35227677 | H8: 26 | I8: 5.4836073
A9: 22 | B9: San Diego St. 5 | C9: =+19.36 -> 19.36 | D9: 113.4 | E9: 94 | F9: =D9^10/(D9^10+E9^10) -> 0.86718165 | G9: =(0.8267556358-0.8267556358*F9)/(0.8267556358+F9-2*0.8267556358*F9) -> 0.42227041 | H9: 22 | I9: =1-G349+5.41620579969999 -> 5.4472733
A10: 5 | B10: Tennessee 2 | C10: =+26.61 -> 26.61 | D10: 116.8 | E10: 90.2 | F10: =D10^10/(D10^10+E10^10) -> 0.92984667 | G10: =(0.8267556358-0.8267556358*F10)/(0.8267556358+F10-2*0.8267556358*F10) -> 0.26472941 | H10: 24 | I10: 5.257271
A11: 4 | B11: Auburn 4 | C11: =+27.99 -> 27.99 | D11: 120.4 | E11: 92.4 | F11: =D11^10/(D11^10+E11^10) -> 0.93382124 | G11: =(0.8267556358-0.8267556358*F11)/(0.8267556358+F11-2*0.8267556358*F11) -> 0.25272723 | H11: 27 | I11: 5.1925005
A12: 6 | B12: Arizona 2 | C12: =+26.55 -> 26.55 | D12: 120.2 | E12: 93.7 | F12: =D12^10/(D12^10+E12^10) -> 0.92347939 | G12: =(0.8267556358-0.8267556358*F12)/(0.8267556358+F12-2*0.8267556358*F12) -> 0.28337486 | H12: 25 | I12: 4.7018639
A13: 54 | B13: South Carolina 6 | C13: =+14.4 -> 14.4 | D13: 114.9 | E13: 100.5 | F13: =D13^10/(D13^10+E13^10) -> 0.79233278 | G13: =(0.8267556358-0.8267556358*F13)/(0.8267556358+F13-2*0.8267556358*F13) -> 0.55570813 | H13: 26 | I13: 4.3846544
A14: 15 | B14: Baylor 3 | C14: =+21.9 -> 21.9 | D14: 122.4 | E14: 100.5 | F14: =D14^10/(D14^10+E14^10) -> 0.87775781 | G14: =(0.8267556358-0.8267556358*F14)/(0.8267556358+F14-2*0.8267556358*F14) -> 0.39925737 | H14: 22 | I14: =1-G361+4.2773538828 -> 4.2951515
A15: 11 | B15: Creighton 3 | C15: =+24.22 -> 24.22 | D15: 120.9 | E15: 96.7 | F15: =D15^10/(D15^10+E15^10) -> 0.90321806 | G15: =(0.8267556358-0.8267556358*F15)/(0.8267556358+F15-2*0.8267556358*F15) -> 0.33834068 | H15: 23 | I15: 3.8443723
A16: 27 | B16: Kansas 4 | C16: =+17.94 -> 17.94 | D16: 113.5 | E16: 95.6 | F16: =D16^10/(D16^10+E16^10) -> 0.84765166 | G16: =(0.8267556358-0.8267556358*F16)/(0.8267556358+F16-2*0.8267556358*F16) -> 0.46170164 | H16: 21 | I16: =1-G351+3.67734548069999 -> 3.7057763
A17: 7 | B17: Duke 4 | C17: =+26.47 -> 26.47 | D17: 121.6 | E17: 95.2 | F17: =D17^10/(D17^10+E17^10) -> 0.92038359 | G17: =(0.8267556358-0.8267556358*F17)/(0.8267556358+F17-2*0.8267556358*F17) -> 0.29219149 | H17: 24 | I17: 3.6216239
A18: 51 | B18: Utah St. 8 | C18: =+14.89 -> 14.89 | D18: 116 | E18: 101.1 | F18: =D18^10/(D18^10+E18^10) -> 0.79815466 | G18: =(0.8267556358-0.8267556358*F18)/(0.8267556358+F18-2*0.8267556358*F18) -> 0.5468634 | H18: 25 | I18: =2*(1-G329)+3.2016820636 -> 3.2882785
A19: 14 | B19: Alabama 4 | C19: =+22.96 -> 22.96 | D19: 126 | E19: 103 | F19: =D19^10/(D19^10+E19^10) -> 0.88241793 | G19: =(0.8267556358-0.8267556358*F19)/(0.8267556358+F19-2*0.8267556358*F19) -> 0.38871351 | H19: 21 | I19: 3.1266432
A20: 31 | B20: Texas Tech 6 | C20: =+17.32 -> 17.32 | D20: 117.4 | E20: 100.1 | F20: =D20^10/(D20^10+E20^10) -> 0.83120229 | G20: =(0.8267556358-0.8267556358*F20)/(0.8267556358+F20-2*0.8267556358*F20) -> 0.49215911 | H20: 23 | I20: 2.7929259
A21: 23 | B21: Kentucky 3 | C21: =+19.29 -> 19.29 | D21: 122.2 | E21: 102.9 | F21: =D21^10/(D21^10+E21^10) -> 0.84800179 | G21: =(0.8267556358-0.8267556358*F21)/(0.8267556358+F21-2*0.8267556358*F21) -> 0.46102722 | H21: 23 | I21: 2.7736794
A22: 21 | B22: St. John's | C22: =+19.41 -> 19.41 | D22: 119 | E22: 99.6 | F22: =D22^10/(D22^10+E22^10) -> 0.85564911 | G22: =(0.8267556358-0.8267556358*F22)/(0.8267556358+F22-2*0.8267556358*F22) -> 0.44600952
A23: 17 | B23: Wisconsin 5 | C23: =+20.06 -> 20.06 | D23: 119.2 | E23: 99.2 | F23: =D23^10/(D23^10+E23^10) -> 0.86255172 | G23: =(0.8267556358-0.8267556358*F23)/(0.8267556358+F23-2*0.8267556358*F23) -> 0.4319643 | H23: 22 | I23: 2.6024959
A24: 40 | B24: Nevada 1No | C24: =+16.41 -> 16.41 | D24: 115 | E24: 98.6 | F24: =D24^10/(D24^10+E24^10) -> 0.82326238 | G24: =(0.8267556358-0.8267556358*F24)/(0.8267556358+F24-2*0.8267556358*F24) -> 0.50604905 | H24: 25 | I24: =1-G346+2.5248977506 -> 2.5584643
A25: 18 | B25: BYU 6 | C25: =+19.96 -> 19.96 | D25: 119.8 | E25: 99.9 | F25: =D25^10/(D25^10+E25^10) -> 0.86015044 | G25: =(0.8267556358-0.8267556358*F25)/(0.8267556358+F25-2*0.8267556358*F25) -> 0.43690466 | H25: 23 | I25: 2.3670074
A26: 26 | B26: Florida 7 | C26: =+18.19 -> 18.19 | D26: 120 | E26: 101.8 | F26: =D26^10/(D26^10+E26^10) -> 0.83818924 | G26: =(0.8267556358-0.8267556358*F26)/(0.8267556358+F26-2*0.8267556358*F26) -> 0.4795089 | H26: 24 | I26: 2.3033396
A27: 52 | B27: Grand Canyon 12 | C27: =+14.84 -> 14.84 | D27: 112.9 | E27: 98.1 | F27: =D27^10/(D27^10+E27^10) -> 0.80300001 | G27: =(0.8267556358-0.8267556358*F27)/(0.8267556358+F27-2*0.8267556358*F27) -> 0.53933232 | H27: 28 | I27: =1-G337 +2.1613539397 -> 2.1987755
A28: 12 | B28: Gonzaga 5 | C28: =+23.17 -> 23.17 | D28: 122.6 | E28: 99.4 | F28: =D28^10/(D28^10+E28^10) -> 0.89068421 | G28: =(0.8267556358-0.8267556358*F28)/(0.8267556358+F28-2*0.8267556358*F28) -> 0.36936474 | H28: 24 | I28: =1-G378 +2.09702988709999 -> 3.0970299
A29: 28 | B29: Wake Forest | C29: =+17.89 -> 17.89 | D29: 117.7 | E29: 99.8 | F29: =D29^10/(D29^10+E29^10) -> 0.83885162 | G29: =(0.8267556358-0.8267556358*F29)/(0.8267556358+F29-2*0.8267556358*F29) -> 0.4782881
A30: 32 | B30: Dayton 7 | C30: =+17.3 -> 17.3 | D30: 117.7 | E30: 100.4 | F30: =D30^10/(D30^10+E30^10) -> 0.83058347 | G30: =(0.8267556358-0.8267556358*F30)/(0.8267556358+F30-2*0.8267556358*F30) -> 0.49325991 | H30: 24 | I30: 2.0253715
A31: 20 | B31: Saint Mary's 5 | C31: =+19.43 -> 19.43 | D31: 114.5 | E31: 95 | F31: =D31^10/(D31^10+E31^10) -> 0.86610837 | G31: =(0.8267556358-0.8267556358*F31)/(0.8267556358+F31-2*0.8267556358*F31) -> 0.42453762 | H31: 25 | I31: =1-G373+1.9395640184 -> 2.939564
A32: 30 | B32: Nebraska 8 | C32: =+17.55 -> 17.55 | D32: 116.2 | E32: 98.7 | F32: =D32^10/(D32^10+E32^10) -> 0.8364816 | G32: =(0.8267556358-0.8267556358*F32)/(0.8267556358+F32-2*0.8267556358*F32) -> 0.48263875 | H32: 23 | I32: 1.9140927
A33: 29 | B33: New Mexico 11 | C33: =+17.8 -> 17.8 | D33: 114.4 | E33: 96.6 | F33: =D33^10/(D33^10+E33^10) -> 0.84438498 | G33: =(0.8267556358-0.8267556358*F33)/(0.8267556358+F33-2*0.8267556358*F33) -> 0.46793972 | H33: 25 | I33: =1-G366+1.8118502865 -> 2.8118503
A34: 33 | B34: Pittsburgh | C34: =+17.18 -> 17.18 | D34: 116.5 | E34: 99.3 | F34: =D34^10/(D34^10+E34^10) -> 0.83166267 | G34: =(0.8267556358-0.8267556358*F34)/(0.8267556358+F34-2*0.8267556358*F34) -> 0.49133813
A35: 42 | B35: Washington St. 7 | C35: =+16.33 -> 16.33 | D35: 113.2 | E35: 96.9 | F35: =D35^10/(D35^10+E35^10) -> 0.82560109 | G35: =(0.8267556358-0.8267556358*F35)/(0.8267556358+F35-2*0.8267556358*F35) -> 0.50200989 | H35: 24 | I35: 1.7466381
A36: 63 | B36: James Madison 12 | C36: =+12.42 -> 12.42 | D36: 113 | E36: 100.6 | F36: =D36^10/(D36^10+E36^10) -> 0.76176048 | G36: =(0.8267556358-0.8267556358*F36)/(0.8267556358+F36-2*0.8267556358*F36) -> 0.59879588 | H36: 30 | I36: =1-G335+1.7173483051 -> 1.75828
A37: 53 | B37: Drake 1No | C37: =+14.53 -> 14.53 | D37: 115.1 | E37: 100.5 | F37: =D37^10/(D37^10+E37^10) -> 0.79517982 | G37: =(0.8267556358-0.8267556358*F37)/(0.8267556358+F37-2*0.8267556358*F37) -> 0.55141022 | H37: 27 | I37: 1.6673008
A38: 37 | B38: VillaNova | C38: =+16.78 -> 16.78 | D38: 111.4 | E38: 94.6 | F38: =D38^10/(D38^10+E38^10) -> 0.83681227 | G38: =(0.8267556358-0.8267556358*F38)/(0.8267556358+F38-2*0.8267556358*F38) -> 0.48203462
A39: 38 | B39: Indiana St. | C39: =+16.69 -> 16.69 | D39: 119.9 | E39: 103.2 | F39: =D39^10/(D39^10+E39^10) -> 0.81755838 | G39: =(0.8267556358-0.8267556358*F39)/(0.8267556358+F39-2*0.8267556358*F39) -> 0.51572331
A40: 39 | B40: Cincinnati | C40: =+16.47 -> 16.47 | D40: 112 | E40: 95.5 | F40: =D40^10/(D40^10+E40^10) -> 0.83113971 | G40: =(0.8267556358-0.8267556358*F40)/(0.8267556358+F40-2*0.8267556358*F40) -> 0.49227057
...

Sheet Wab2023
A1: Rk | B1: Team | C1: Tourney | D1: NetRtg | E1: ORtg | F1: DRtg | G1: AvgWin | H1: Bubble Win | I1: Wab
A2: 9 | B2: Kansas | C2: Yes | D2: =+22.85 -> 22.85 | E2: 114.6 | F2: 91.8 | G2: =E2^10/(E2^10+F2^10) -> 0.90188574 | H2: =(0.7816202012-0.7816202012*G2)/(0.7816202012+G2-2*0.7816202012*G2) -> 0.28025 | I2: 11.145409
A3: 4 | B3: Alabama | C3: Yes | D3: =+27.28 -> 27.28 | E3: 115.5 | F3: 88.2 | G3: =E3^10/(E3^10+F3^10) -> 0.93682783 | H3: =(0.7816202012-0.7816202012*G3)/(0.7816202012+G3-2*0.7816202012*G3) -> 0.19442615 | I3: 11.037367
A4: 7 | B4: Purdue | C4: Yes | D4: =+23.24 -> 23.24 | E4: 117.7 | F4: 94.5 | G4: =E4^10/(E4^10+F4^10) -> 0.89983493 | H4: =(0.7816202012-0.7816202012*G4)/(0.7816202012+G4-2*0.7816202012*G4) -> 0.28490521 | I4: 10.467536
A5: 3 | B5: UCLA | C5: Yes | D5: =+27.29 -> 27.29 | E5: 115.2 | F5: 88 | G5: =E5^10/(E5^10+F5^10) -> 0.93663187 | H5: =(0.7816202012-0.7816202012*G5)/(0.7816202012+G5-2*0.7816202012*G5) -> 0.19494453 | I5: 9.3720506
A6: 10 | B6: Marquette | C6: Yes | D6: =+22.38 -> 22.38 | E6: 119.1 | F6: 96.7 | G6: =E6^10/(E6^10+F6^10) -> 0.88928916 | H6: =(0.7816202012-0.7816202012*G6)/(0.7816202012+G6-2*0.7816202012*G6) -> 0.30823847 | I6: 9.0555468
A7: 2 | B7: Houston | C7: Yes | D7: =+27.72 -> 27.72 | E7: 118.1 | F7: 90.4 | G7: =E7^10/(E7^10+F7^10) -> 0.93540693 | H7: =(0.7816202012-0.7816202012*G7)/(0.7816202012+G7-2*0.7816202012*G7) -> 0.19817477 | I7: 9.0396905
A8: 5 | B8: Texas | C8: Yes | D8: =+24.43 -> 24.43 | E8: 116.5 | F8: 92.1 | G8: =E8^10/(E8^10+F8^10) -> 0.91294721 | H8: =(0.7816202012-0.7816202012*G8)/(0.7816202012+G8-2*0.7816202012*G8) -> 0.25444768 | I8: 8.9853682
A9: 8 | B9: Gonzaga | C9: Yes | D9: =+23.02 -> 23.02 | E9: 122.3 | F9: 99.3 | G9: =E9^10/(E9^10+F9^10) -> 0.88927085 | H9: =(0.7816202012-0.7816202012*G9)/(0.7816202012+G9-2*0.7816202012*G9) -> 0.30827814 | I9: =1-H364+7.91968345479999 -> 7.9344884
A10: 11 | B10: Arizona | C10: Yes | D10: =+21.9 -> 21.9 | E10: 118.2 | F10: 96.3 | G10: =E10^10/(E10^10+F10^10) -> 0.88585643 | H10: =(0.7816202012-0.7816202012*G10)/(0.7816202012+G10-2*0.7816202012*G10) -> 0.3156221 | I10: 8.7308792
A11: 14 | B11: San Diego State | C11: Yes | D11: =+20.34 -> 20.34 | E11: 110.8 | F11: 90.4 | G11: =E11^10/(E11^10+F11^10) -> 0.88440527 | H11: =(0.7816202012-0.7816202012*G11)/(0.7816202012+G11-2*0.7816202012*G11) -> 0.31871317 | I11: =1-H360+7.0201719821 -> 7.0538121
A12: 15 | B12: Xavier | C12: Yes | D12: =+19.95 -> 19.95 | E12: 118.5 | F12: 98.6 | G12: =E12^10/(E12^10+F12^10) -> 0.86276138 | H12: =(0.7816202012-0.7816202012*G12)/(0.7816202012+G12-2*0.7816202012*G12) -> 0.362788 | I12: 6.6856874
A13: 16 | B13: Baylor | C13: Yes | D13: =+19.68 -> 19.68 | E13: 121.3 | F13: 101.6 | G13: =E13^10/(E13^10+F13^10) -> 0.85473512 | H13: =(0.7816202012-0.7816202012*G13)/(0.7816202012+G13-2*0.7816202012*G13) -> 0.37822251 | I13: 6.3674021
A14: 1 | B14: Connecticut | C14: Yes | D14: =+29.86 -> 29.86 | E14: 120.8 | F14: 90.9 | G14: =E14^10/(E14^10+F14^10) -> 0.94499538 | H14: =(0.7816202012-0.7816202012*G14)/(0.7816202012+G14-2*0.7816202012*G14) -> 0.17241184 | I14: 6.3323355
A15: 13 | B15: Saint Mary's (CA) | C15: Yes | D15: =+21.24 -> 21.24 | E15: 112.6 | F15: 91.4 | G15: =E15^10/(E15^10+F15^10) -> 0.88953129 | H15: =(0.7816202012-0.7816202012*G15)/(0.7816202012+G15-2*0.7816202012*G15) -> 0.30771383 | I15: =1-H365 + 5.2713432059 -> 6.2713432
A16: 17 | B16: Florida Atlantic | C16: Yes | D16: =+19.38 -> 19.38 | E16: 115.1 | F16: 95.7 | G16: =E16^10/(E16^10+F16^10) -> 0.86363677 | H16: =(0.7816202012-0.7816202012*G16)/(0.7816202012+G16-2*0.7816202012*G16) -> 0.36107602 | I16: =1-H362+5.8917035037 -> 5.9128001
A17: 21 | B17: Kansas State | C17: Yes | D17: =+18.51 -> 18.51 | E17: 113.5 | F17: 95 | G17: =E17^10/(E17^10+F17^10) -> 0.8556054 | H17: =(0.7816202012-0.7816202012*G17)/(0.7816202012+G17-2*0.7816202012*G17) -> 0.37657148 | I17: 5.6654038
A18: 20 | B18: Memphis | C18: Yes | D18: =+18.53 -> 18.53 | E18: 114.6 | F18: 96.1 | G18: =E18^10/(E18^10+F18^10) -> 0.8532829 | H18: =(0.7816202012-0.7816202012*G18)/(0.7816202012+G18-2*0.7816202012*G18) -> 0.38096562 | I18: 5.4810371
A19: 18 | B19: Duke | C19: Yes | D19: =+19.35 -> 19.35 | E19: 113.2 | F19: 93.9 | G19: =E19^10/(E19^10+F19^10) -> 0.86637237 | H19: =(0.7816202012-0.7816202012*G19)/(0.7816202012+G19-2*0.7816202012*G19) -> 0.35568904 | I19: 5.4637173
A20: 24 | B20: Miami (FL) | C20: Yes | D20: =+17.94 -> 17.94 | E20: 119.1 | F20: 101.2 | G20: =E20^10/(E20^10+F20^10) -> 0.83598423 | H20: =(0.7816202012-0.7816202012*G20)/(0.7816202012+G20-2*0.7816202012*G20) -> 0.41253055 | I20: 5.0059295
A21: 28 | B21: Utah State | C21: Yes | D21: =+17.39 -> 17.39 | E21: 116.3 | F21: 98.9 | G21: =E21^10/(E21^10+F21^10) -> 0.83488313 | H21: =(0.7816202012-0.7816202012*G21)/(0.7816202012+G21-2*0.7816202012*G21) -> 0.41447287 | I21: =1-H356+4.7473302062 -> 4.7846673
A22: 57 | B22: Missouri | C22: Yes | D22: =+13.07 -> 13.07 | E22: 118.3 | F22: 105.3 | G22: =E22^10/(E22^10+F22^10) -> 0.76207755 | H22: =(0.7816202012-0.7816202012*G22)/(0.7816202012+G22-2*0.7816202012*G22) -> 0.52772894 | I22: 4.7185385
A23: 33 | B23: Texas A&M | C23: Yes | D23: =+16.71 -> 16.71 | E23: 113.7 | F23: 97 | G23: =E23^10/(E23^10+F23^10) -> 0.83040837 | H23: =(0.7816202012-0.7816202012*G23)/(0.7816202012+G23-2*0.7816202012*G23) -> 0.42228725 | I23: 4.6809007
A24: 30 | B24: Indiana | C24: Yes | D24: =+17.03 -> 17.03 | E24: 114.2 | F24: 97.2 | G24: =E24^10/(E24^10+F24^10) -> 0.83366196 | H24: =(0.7816202012-0.7816202012*G24)/(0.7816202012+G24-2*0.7816202012*G24) -> 0.41661795 | I24: 4.4375865
A25: 34 | B25: Virginia | C25: Yes | D25: =+16.37 -> 16.37 | E25: 110.8 | F25: 94.5 | G25: =E25^10/(E25^10+F25^10) -> 0.83079462 | H25: =(0.7816202012-0.7816202012*G25)/(0.7816202012+G25-2*0.7816202012*G25) -> 0.42161767 | I25: 4.1913241
